{"trial_id": "0000", "hyperparameters": {"space": [{"class_name": "Choice", "config": {"name": "activation", "default": "relu", "conditions": [], "values": ["relu", "tanh"], "ordered": false}}, {"class_name": "Int", "config": {"name": "layer_1", "default": null, "conditions": [], "min_value": 1, "max_value": 1000, "step": 100, "sampling": "linear"}}, {"class_name": "Int", "config": {"name": "layer_2", "default": null, "conditions": [], "min_value": 1, "max_value": 1000, "step": 100, "sampling": "linear"}}, {"class_name": "Choice", "config": {"name": "learning_rate", "default": 0.01, "conditions": [], "values": [0.01, 0.001, 0.0001], "ordered": true}}], "values": {"activation": "tanh", "layer_1": 701, "layer_2": 201, "learning_rate": 0.0001, "tuner/epochs": 2, "tuner/initial_epoch": 0, "tuner/bracket": 2, "tuner/round": 0}}, "metrics": {"metrics": {}}, "score": null, "best_step": 0, "status": "FAILED", "message": "Traceback (most recent call last):\n  File \"/home/bruno/.local/lib/python3.10/site-packages/keras_tuner/src/engine/base_tuner.py\", line 274, in _try_run_and_update_trial\n    self._run_and_update_trial(trial, *fit_args, **fit_kwargs)\n  File \"/home/bruno/.local/lib/python3.10/site-packages/keras_tuner/src/engine/base_tuner.py\", line 239, in _run_and_update_trial\n    results = self.run_trial(trial, *fit_args, **fit_kwargs)\n  File \"/home/bruno/.local/lib/python3.10/site-packages/keras_tuner/src/tuners/hyperband.py\", line 427, in run_trial\n    return super().run_trial(trial, *fit_args, **fit_kwargs)\n  File \"/home/bruno/.local/lib/python3.10/site-packages/keras_tuner/src/engine/tuner.py\", line 314, in run_trial\n    obj_value = self._build_and_fit_model(trial, *args, **copied_kwargs)\n  File \"/home/bruno/.local/lib/python3.10/site-packages/keras_tuner/src/engine/tuner.py\", line 233, in _build_and_fit_model\n    results = self.hypermodel.fit(hp, model, *args, **kwargs)\n  File \"/home/bruno/.local/lib/python3.10/site-packages/keras_tuner/src/engine/hypermodel.py\", line 149, in fit\n    return model.fit(*args, **kwargs)\n  File \"/home/bruno/.local/lib/python3.10/site-packages/keras/src/utils/traceback_utils.py\", line 122, in error_handler\n    raise e.with_traceback(filtered_tb) from None\n  File \"/home/bruno/.local/lib/python3.10/site-packages/tensorflow/python/eager/execute.py\", line 53, in quick_execute\n    tensors = pywrap_tfe.TFE_Py_Execute(ctx._handle, device_name, op_name,\ntensorflow.python.framework.errors_impl.InvalidArgumentError: Graph execution error:\n\nDetected at node compile_loss/sparse_categorical_crossentropy/SparseSoftmaxCrossEntropyWithLogits/SparseSoftmaxCrossEntropyWithLogits defined at (most recent call last):\n  File \"/usr/lib/python3.10/runpy.py\", line 196, in _run_module_as_main\n\n  File \"/usr/lib/python3.10/runpy.py\", line 86, in _run_code\n\n  File \"/home/bruno/.local/lib/python3.10/site-packages/ipykernel_launcher.py\", line 18, in <module>\n\n  File \"/home/bruno/.local/lib/python3.10/site-packages/traitlets/config/application.py\", line 1075, in launch_instance\n\n  File \"/home/bruno/.local/lib/python3.10/site-packages/ipykernel/kernelapp.py\", line 739, in start\n\n  File \"/home/bruno/.local/lib/python3.10/site-packages/tornado/platform/asyncio.py\", line 205, in start\n\n  File \"/usr/lib/python3.10/asyncio/base_events.py\", line 603, in run_forever\n\n  File \"/usr/lib/python3.10/asyncio/base_events.py\", line 1909, in _run_once\n\n  File \"/usr/lib/python3.10/asyncio/events.py\", line 80, in _run\n\n  File \"/home/bruno/.local/lib/python3.10/site-packages/ipykernel/kernelbase.py\", line 545, in dispatch_queue\n\n  File \"/home/bruno/.local/lib/python3.10/site-packages/ipykernel/kernelbase.py\", line 534, in process_one\n\n  File \"/home/bruno/.local/lib/python3.10/site-packages/ipykernel/kernelbase.py\", line 437, in dispatch_shell\n\n  File \"/home/bruno/.local/lib/python3.10/site-packages/ipykernel/ipkernel.py\", line 359, in execute_request\n\n  File \"/home/bruno/.local/lib/python3.10/site-packages/ipykernel/kernelbase.py\", line 778, in execute_request\n\n  File \"/home/bruno/.local/lib/python3.10/site-packages/ipykernel/ipkernel.py\", line 446, in do_execute\n\n  File \"/home/bruno/.local/lib/python3.10/site-packages/ipykernel/zmqshell.py\", line 549, in run_cell\n\n  File \"/home/bruno/.local/lib/python3.10/site-packages/IPython/core/interactiveshell.py\", line 3075, in run_cell\n\n  File \"/home/bruno/.local/lib/python3.10/site-packages/IPython/core/interactiveshell.py\", line 3130, in _run_cell\n\n  File \"/home/bruno/.local/lib/python3.10/site-packages/IPython/core/async_helpers.py\", line 129, in _pseudo_sync_runner\n\n  File \"/home/bruno/.local/lib/python3.10/site-packages/IPython/core/interactiveshell.py\", line 3334, in run_cell_async\n\n  File \"/home/bruno/.local/lib/python3.10/site-packages/IPython/core/interactiveshell.py\", line 3517, in run_ast_nodes\n\n  File \"/home/bruno/.local/lib/python3.10/site-packages/IPython/core/interactiveshell.py\", line 3577, in run_code\n\n  File \"/tmp/ipykernel_78030/608998110.py\", line 3, in <module>\n\n  File \"/home/bruno/.local/lib/python3.10/site-packages/keras_tuner/src/engine/base_tuner.py\", line 234, in search\n\n  File \"/home/bruno/.local/lib/python3.10/site-packages/keras_tuner/src/engine/base_tuner.py\", line 274, in _try_run_and_update_trial\n\n  File \"/home/bruno/.local/lib/python3.10/site-packages/keras_tuner/src/engine/base_tuner.py\", line 239, in _run_and_update_trial\n\n  File \"/home/bruno/.local/lib/python3.10/site-packages/keras_tuner/src/tuners/hyperband.py\", line 427, in run_trial\n\n  File \"/home/bruno/.local/lib/python3.10/site-packages/keras_tuner/src/engine/tuner.py\", line 314, in run_trial\n\n  File \"/home/bruno/.local/lib/python3.10/site-packages/keras_tuner/src/engine/tuner.py\", line 233, in _build_and_fit_model\n\n  File \"/home/bruno/.local/lib/python3.10/site-packages/keras_tuner/src/engine/hypermodel.py\", line 149, in fit\n\n  File \"/home/bruno/.local/lib/python3.10/site-packages/keras/src/utils/traceback_utils.py\", line 117, in error_handler\n\n  File \"/home/bruno/.local/lib/python3.10/site-packages/keras/src/backend/tensorflow/trainer.py\", line 314, in fit\n\n  File \"/home/bruno/.local/lib/python3.10/site-packages/keras/src/backend/tensorflow/trainer.py\", line 117, in one_step_on_iterator\n\n  File \"/home/bruno/.local/lib/python3.10/site-packages/keras/src/backend/tensorflow/trainer.py\", line 104, in one_step_on_data\n\n  File \"/home/bruno/.local/lib/python3.10/site-packages/keras/src/backend/tensorflow/trainer.py\", line 54, in train_step\n\n  File \"/home/bruno/.local/lib/python3.10/site-packages/keras/src/trainers/trainer.py\", line 316, in compute_loss\n\n  File \"/home/bruno/.local/lib/python3.10/site-packages/keras/src/trainers/compile_utils.py\", line 609, in __call__\n\n  File \"/home/bruno/.local/lib/python3.10/site-packages/keras/src/trainers/compile_utils.py\", line 645, in call\n\n  File \"/home/bruno/.local/lib/python3.10/site-packages/keras/src/losses/loss.py\", line 43, in __call__\n\n  File \"/home/bruno/.local/lib/python3.10/site-packages/keras/src/losses/losses.py\", line 22, in call\n\n  File \"/home/bruno/.local/lib/python3.10/site-packages/keras/src/losses/losses.py\", line 1722, in sparse_categorical_crossentropy\n\n  File \"/home/bruno/.local/lib/python3.10/site-packages/keras/src/ops/nn.py\", line 1567, in sparse_categorical_crossentropy\n\n  File \"/home/bruno/.local/lib/python3.10/site-packages/keras/src/backend/tensorflow/nn.py\", line 638, in sparse_categorical_crossentropy\n\nReceived a label value of 1 which is outside the valid range of [0, 1).  Label values: 0 0 1 1 0 1 1 0 0 0 1 0 0 1 1 1 1 0 1 1 1 0 1 0 0 1 0 1 1 1 0 1\n\t [[{{node compile_loss/sparse_categorical_crossentropy/SparseSoftmaxCrossEntropyWithLogits/SparseSoftmaxCrossEntropyWithLogits}}]] [Op:__inference_one_step_on_iterator_2714762]\n"}